<?xml version="1.0" encoding="utf-8"?>
<!-- This URDF was automatically created by SolidWorks to URDF Exporter! Originally created by Stephen Brawner (brawner@gmail.com) 
     Commit Version: 1.6.0-1-g15f4949  Build Version: 1.6.7594.29634
     For more information, please see http://wiki.ros.org/sw_urdf_exporter -->
<robot
  name="URDF.SLDASM">
  <link
    name="base_link">
    <inertial>
      <origin
        xyz="-6.64882731495249E-05 7.85530534534538E-08 0.0372113793508206"
        rpy="0 0 0" />
      <mass
        value="0.826569047112773" />
      <inertia
        ixx="0.00128317926906273"
        ixy="3.07837926699108E-09"
        ixz="1.1512899172121E-09"
        iyy="0.0019361502670081"
        iyz="9.46148198492292E-10"
        izz="0.00129114002024673" />
    </inertial>
    <visual>
      <origin
        xyz="0 0 0"
        rpy="0 0 0" />
      <geometry>
        <mesh
          filename="package://URDF.SLDASM/meshes/base_link.STL" />
      </geometry>
      <material
        name="">
        <color
          rgba="0.752941176470588 0.752941176470588 0.752941176470588 1" />
      </material>
    </visual>
    <collision>
      <origin
        xyz="0 0 0"
        rpy="0 0 0" />
      <geometry>
        <mesh
          filename="package://URDF.SLDASM/meshes/base_link.STL" />
      </geometry>
    </collision>
  </link>
  <link
    name="Link1">
    <inertial>
      <origin
        xyz="-0.000166723285039962 3.99242581691177E-05 0.0364606307193845"
        rpy="0 0 0" />
      <mass
        value="0.336146612178727" />
      <inertia
        ixx="0.000200165674616881"
        ixy="-1.63989090796318E-09"
        ixz="-3.49362522029313E-07"
        iyy="0.000195186011544854"
        iyz="2.59258046646595E-09"
        izz="0.00018163132991926" />
    </inertial>
    <visual>
      <origin
        xyz="0 0 0"
        rpy="0 0 0" />
      <geometry>
        <mesh
          filename="package://URDF.SLDASM/meshes/Link1.STL" />
      </geometry>
      <material
        name="">
        <color
          rgba="0.752941176470588 0.752941176470588 0.752941176470588 1" />
      </material>
    </visual>
    <collision>
      <origin
        xyz="0 0 0"
        rpy="0 0 0" />
      <geometry>
        <mesh
          filename="package://URDF.SLDASM/meshes/Link1.STL" />
      </geometry>
    </collision>
  </link>
  <joint
    name="Joint0"
    type="continuous">
    <origin
      xyz="0 0 0.124"
      rpy="0 0 -0.0649357797465708" />
    <parent
      link="base_link" />
    <child
      link="Link1" />
    <axis
      xyz="0 0 1" />
  </joint>
  <link
    name="Link2">
    <inertial>
      <origin
        xyz="-0.00103364381428033 0.00282106294471786 0.240959238482709"
        rpy="0 0 0" />
      <mass
        value="1.52616310106415" />
      <inertia
        ixx="0.0126688243865777"
        ixy="1.54927696827166E-09"
        ixz="2.61016168962436E-07"
        iyy="0.0129494550255387"
        iyz="-5.38543874033167E-09"
        izz="0.00116606729126069" />
    </inertial>
    <visual>
      <origin
        xyz="0 0 0"
        rpy="0 0 0" />
      <geometry>
        <mesh
          filename="package://URDF.SLDASM/meshes/Link2.STL" />
      </geometry>
      <material
        name="">
        <color
          rgba="0.752941176470588 0.752941176470588 0.752941176470588 1" />
      </material>
    </visual>
    <collision>
      <origin
        xyz="0 0 0"
        rpy="0 0 0" />
      <geometry>
        <mesh
          filename="package://URDF.SLDASM/meshes/Link2.STL" />
      </geometry>
    </collision>
  </link>
  <joint
    name="Joint1"
    type="continuous">
    <origin
      xyz="0 0 0.05"
      rpy="-0.491164443798803 0 0" />
    <parent
      link="Link1" />
    <child
      link="Link2" />
    <axis
      xyz="1 0 0" />
  </joint>
  <link
    name="Link3">
    <inertial>
      <origin
        xyz="-0.00200005155118979 -1.28225251305736E-07 0.273278911663861"
        rpy="0 0 0" />
      <mass
        value="1.72916992416721" />
      <inertia
        ixx="0.0131991209795048"
        ixy="2.33957970176475E-09"
        ixz="1.07739684571627E-09"
        iyy="0.0133695518791343"
        iyz="2.95897081974434E-10"
        izz="0.0012355742316079" />
    </inertial>
    <visual>
      <origin
        xyz="0 0 0"
        rpy="0 0 0" />
      <geometry>
        <mesh
          filename="package://URDF.SLDASM/meshes/Link3.STL" />
      </geometry>
      <material
        name="">
        <color
          rgba="0.752941176470588 0.752941176470588 0.752941176470588 1" />
      </material>
    </visual>
    <collision>
      <origin
        xyz="0 0 0"
        rpy="0 0 0" />
      <geometry>
        <mesh
          filename="package://URDF.SLDASM/meshes/Link3.STL" />
      </geometry>
    </collision>
  </link>
  <joint
    name="Joint2"
    type="continuous">
    <origin
      xyz="0 0.00282991797538142 0.393220402882636"
      rpy="-1.34047867238601 0 0" />
    <parent
      link="Link2" />
    <child
      link="Link3" />
    <axis
      xyz="1 0 0" />
  </joint>
  <link
    name="Link4">
    <inertial>
      <origin
        xyz="3.99435641686985E-05 0.000166550965478685 0.0375140550632704"
        rpy="0 0 0" />
      <mass
        value="0.33614578602941" />
      <inertia
        ixx="0.000195186061386812"
        ixy="1.01068337539693E-09"
        ixz="2.51216636781883E-09"
        iyy="0.000200166580317713"
        iyz="3.49496476758147E-07"
        izz="0.00018163206778205" />
    </inertial>
    <visual>
      <origin
        xyz="0 0 0"
        rpy="0 0 0" />
      <geometry>
        <mesh
          filename="package://URDF.SLDASM/meshes/Link4.STL" />
      </geometry>
      <material
        name="">
        <color
          rgba="0.752941176470588 0.752941176470588 0.752941176470588 1" />
      </material>
    </visual>
    <collision>
      <origin
        xyz="0 0 0"
        rpy="0 0 0" />
      <geometry>
        <mesh
          filename="package://URDF.SLDASM/meshes/Link4.STL" />
      </geometry>
    </collision>
  </link>
  <joint
    name="Joint3"
    type="continuous">
    <origin
      xyz="-0.00199999999999989 0 0.499457607867746"
      rpy="0 0 0.536640228499924" />
    <parent
      link="Link3" />
    <child
      link="Link4" />
    <axis
      xyz="0 0 1" />
  </joint>
  <link
    name="Link5">
    <inertial>
      <origin
        xyz="-0.000975750985627355 0.000722913552429177 0.104906752760861"
        rpy="0 0 0" />
      <mass
        value="0.55697534535204" />
      <inertia
        ixx="0.000528184542778978"
        ixy="-6.60880841198141E-09"
        ixz="1.06627678868586E-09"
        iyy="0.000542241783937023"
        iyz="-1.42721121157382E-09"
        izz="0.000323926239054427" />
    </inertial>
    <visual>
      <origin
        xyz="0 0 0"
        rpy="0 0 0" />
      <geometry>
        <mesh
          filename="package://URDF.SLDASM/meshes/Link5.STL" />
      </geometry>
      <material
        name="">
        <color
          rgba="0.752941176470588 0.752941176470588 0.752941176470588 1" />
      </material>
    </visual>
    <collision>
      <origin
        xyz="0 0 0"
        rpy="0 0 0" />
      <geometry>
        <mesh
          filename="package://URDF.SLDASM/meshes/Link5.STL" />
      </geometry>
    </collision>
  </link>
  <joint
    name="Joint4"
    type="continuous">
    <origin
      xyz="0 0 0.0499999999999999"
      rpy="-0.141756156992662 0 1.57079632679489" />
    <parent
      link="Link4" />
    <child
      link="Link5" />
    <axis
      xyz="1 0 0" />
  </joint>
  <link
    name="Link6">
    <inertial>
      <origin
        xyz="-1.11022302462516E-16 0.00565280918491384 0"
        rpy="0 0 0" />
      <mass
        value="0.0124187157596404" />
      <inertia
        ixx="1.57736739923924E-06"
        ixy="6.45200877791362E-22"
        ixz="-1.05879118406788E-22"
        iyy="2.85494274430196E-06"
        iyz="4.63221143029695E-23"
        izz="1.57736739923924E-06" />
    </inertial>
    <visual>
      <origin
        xyz="0 0 0"
        rpy="0 0 0" />
      <geometry>
        <mesh
          filename="package://URDF.SLDASM/meshes/Link6.STL" />
      </geometry>
      <material
        name="">
        <color
          rgba="0.792156862745098 0.819607843137255 0.933333333333333 1" />
      </material>
    </visual>
    <collision>
      <origin
        xyz="0 0 0"
        rpy="0 0 0" />
      <geometry>
        <mesh
          filename="package://URDF.SLDASM/meshes/Link6.STL" />
      </geometry>
    </collision>
  </link>
  <joint
    name="Joint5"
    type="continuous">
    <origin
      xyz="-0.00100000000000011 0.000698850719416777 0.197138621123125"
      rpy="1.5707963267949 0 2.88539806004341" />
    <parent
      link="Link5" />
    <child
      link="Link6" />
    <axis
      xyz="0 -1 0" />
  </joint>
</robot>